Workbook

Sheet PRICING
B2: SEATO PRICING (not final)
B4: Subscription | C4: Price | D4: Time | E4: x. Composition | H4: 1 year | K4: 1m 3b | L4: 1m 6b | M4: 1m 12b | O4: 3m 3b
B5: Starter | C5: 299000 | D5: @/month | E5: 0.3 | H5: =C5*12 -> 3588000 | I5: 0.15 | K5: =$I$5*$C$5*3 -> 134550 | L5: =$I$5*$C$5*6 -> 269100 | M5: =$I$5*$C$5*12 -> 538200 | O5: =3*K5 -> 403650
B6: Professional | C6: 599000 | D6: @/month | E6: 0.5 | H6: =C6*12 -> 7188000 | I6: 0.12 | K6: =$I$6*$C$6*3 -> 215640 | L6: =$I$6*$C$6*6 -> 431280 | M6: =$I$6*$C$6*12 -> 862560 | O6: =3*K6 -> 646920
B7: Enterprise | C7: 799000 | D7: @/month | E7: 0.2 | H7: =C7*12 -> 9588000 | I7: 0.1 | K7: =$I$7*$C$7*3 -> 239700 | L7: =$I$7*$C$7*6 -> 479400 | M7: =$I$7*$C$7*12 -> 958800 | O7: =3*K7 -> 719100
B9: Promotion CPM | C9: CPM
B10: Hero Banner | C10: 15000 | E10: Avg. Promotion Cost | F10: =AVERAGE(C10:C13) -> 16250
B11: Featured Merchant | C11: 15000
B12: Push Notification | C12: 20000
B13: Sponsored Listing | C13: 15000
B16: Key Assumption | C16: Value
B17: Initial Merchant | C17: 50
B18: Initial User | C18: 1000
B19: Merchant CAC | C19: 200000
B20: Merchant Retention | C20: 0.85
B21: Promotion Purchase Rate | C21: 0.3
B22: x. Impression @/month | C22: 10000 | D22: views (st. month) | E22: x. growing exponentially

Sheet GROWTH PROJECTION
B2: GROWTH PROJECTION (not final)
B4: Year 1 | F4: Year 2 | J4: Year 3
B5: Month | C5: Merchant | D5: User | F5: Month | G5: Merchant | H5: User | J5: Month | K5: Merchant | L5: User
B6: 1 | C6: 50 | D6: 1000 | F6: 1 | G6: 400 | J6: 1
B7: 2 | C7: 65 | D7: 1800 | F7: 2 | J7: 2
B8: 3 | C8: 82 | D8: 3000 | F8: 3 | J8: 3
B9: 4 | C9: 100 | D9: 4500 | F9: 4 | J9: 4
B10: 5 | C10: 120 | D10: 6500 | F10: 5 | J10: 5
B11: 6 | C11: 145 | D11: 9000 | F11: 6 | J11: 6
B12: 7 | C12: 170 | D12: 12000 | F12: 7 | J12: 7
B13: 8 | C13: 200 | D13: 16000 | F13: 8 | J13: 8
B14: 9 | C14: 230 | D14: 21000 | F14: 9 | J14: 9
B15: 10 | C15: 265 | D15: 27000 | F15: 10 | J15: 10
B16: 11 | C16: 300 | D16: 34000 | F16: 11 | J16: 11
B17: 12 | C17: 340 | D17: 42000 | F17: 12 | J17: 12
B19: Year 4 | F19: Year 5
B20: Month | C20: Merchant | D20: User | F20: Month | G20: Merchant | H20: User
B21: 1 | F21: 1
B22: 2 | F22: 2
B23: 3 | F23: 3
B24: 4 | F24: 4
B25: 5 | F25: 5
B26: 6 | F26: 6
B27: 7 | F27: 7
B28: 8 | F28: 8
B29: 9 | F29: 9
B30: 10 | F30: 10
B31: 11 | F31: 11
B32: 12 | F32: 12

Sheet REVENUE MODEL
B2: REVENUE MODEL (not final)
B4: MODEL 1 (HIGH-BISMILLAH)
C5: M1 | D5: M2 | E5: M3 | F5: M4 | G5: M5 | H5: M6 | I5: M7 | J5: M8 | K5: M9 | L5: M10 | M5: M11 | N5: M12 | O5: TOTAL
B6: Merchant | C6: 50 | D6: 65 | E6: 82 | F6: 100 | G6: 120 | H6: 145 | I6: 170 | J6: 200 | K6: 230 | L6: 265 | M6: 300 | N6: 340
B7: Starter | C7: =30%*C6 -> 15 | D7: =30%*D6+0.5 -> 20 | E7: =30%*E6+0.4 -> 25 | F7: =30%*F6 -> 30 | G7: =30%*G6 -> 36 | H7: =30%*H6+0.5 -> 44 | I7: =30%*I6 -> 51 | J7: =30%*J6 -> 60 | K7: =30%*K6 -> 69 | L7: =30%*L6+0.5 -> 80 | M7: =30%*M6 -> 90 | N7: =30%*N6 -> 102
B8: Professional | C8: =50%*C6 -> 25 | D8: =50%*D6-0.5 -> 32 | E8: =50%*E6 -> 41 | F8: =50%*F6 -> 50 | G8: =50%*G6 -> 60 | H8: =50%*H6-0.5 -> 72 | I8: =50%*I6 -> 85 | J8: =50%*J6 -> 100 | K8: =50%*K6 -> 115 | L8: =50%*L6-0.5 -> 132 | M8: =50%*M6 -> 150 | N8: =50%*N6 -> 170
B9: Enterprise | C9: =20%*C6 -> 10 | D9: =20%*D6 -> 13 | E9: =20%*E6-0.4 -> 16 | F9: =20%*F6 -> 20 | G9: =20%*G6 -> 24 | H9: =20%*H6 -> 29 | I9: =20%*I6 -> 34 | J9: =20%*J6 -> 40 | K9: =20%*K6 -> 46 | L9: =20%*L6 -> 53 | M9: =20%*M6 -> 60 | N9: =20%*N6 -> 68
B10: Subscription Revenue | C10: =(C7*PRICING!$C$5)+(C8*PRICING!$C$6)+(C9*PRICING!$C$7) -> 27450000 | D10: =(D7*PRICING!$C$5)+(D8*PRICING!$C$6)+(D9*PRICING!$C$7) -> 35535000 | E10: =(E7*PRICING!$C$5)+(E8*PRICING!$C$6)+(E9*PRICING!$C$7) -> 44818000 | F10: =(F7*PRICING!$C$5)+(F8*PRICING!$C$6)+(F9*PRICING!$C$7) -> 54900000 | G10: =(G7*PRICING!$C$5)+(G8*PRICING!$C$6)+(G9*PRICING!$C$7) -> 65880000 | H10: =(H7*PRICING!$C$5)+(H8*PRICING!$C$6)+(H9*PRICING!$C$7) -> 79455000 | I10: =(I7*PRICING!$C$5)+(I8*PRICING!$C$6)+(I9*PRICING!$C$7) -> 93330000 | J10: =(J7*PRICING!$C$5)+(J8*PRICING!$C$6)+(J9*PRICING!$C$7) -> 109800000 | ... N10: =(N7*PRICING!$C$5)+(N8*PRICING!$C$6)+(N9*PRICING!$C$7) -> 186660000 | O10: =SUM(C10:N10) -> 1134133000
B11: Promotion Revenue | C11: =C6*PRICING!$C$21*(PRICING!$C$22/1000)*PRICING!$F$10 -> 2437500 | D11: =D6*PRICING!$C$21*(PRICING!$C$22/1000)*PRICING!$F$10 -> 3168750 | E11: =E6*PRICING!$C$21*(PRICING!$C$22/1000)*PRICING!$F$10 -> 3997500 | F11: =F6*PRICING!$C$21*(PRICING!$C$22/1000)*PRICING!$F$10 -> 4875000 | G11: =G6*PRICING!$C$21*(PRICING!$C$22/1000)*PRICING!$F$10 -> 5850000 | H11: =H6*PRICING!$C$21*(PRICING!$C$22/1000)*PRICING!$F$10 -> 7068750 | I11: =I6*PRICING!$C$21*(PRICING!$C$22/1000)*PRICING!$F$10 -> 8287500 | J11: =J6*PRICING!$C$21*(PRICING!$C$22/1000)*PRICING!$F$10 -> 9750000 | ... N11: =N6*PRICING!$C$21*(PRICING!$C$22/1000)*PRICING!$F$10 -> 16575000 | O11: =SUM(C11:N11) -> 100766250
B12: Total Revenue | C12: =SUM(C10:C11) -> 29887500 | D12: =SUM(D10:D11) -> 38703750 | E12: =SUM(E10:E11) -> 48815500 | F12: =SUM(F10:F11) -> 59775000 | G12: =SUM(G10:G11) -> 71730000 | H12: =SUM(H10:H11) -> 86523750 | I12: =SUM(I10:I11) -> 101617500 | J12: =SUM(J10:J11) -> 119550000 | ... N12: =SUM(N10:N11) -> 203235000 | O12: =SUM(C12:N12) -> 1234899250
B14: ARPM | C14: =C12/C6 -> 597750 | D14: =D12/D6 -> 595442.31 | E14: =E12/E6 -> 595310.98 | F14: =F12/F6 -> 597750 | G14: =G12/G6 -> 597750 | H14: =H12/H6 -> 596715.52 | I14: =I12/I6 -> 597750 | J14: =J12/J6 -> 597750 | ... N14: =N12/N6 -> 597750
B16: MODEL 2 (MID)
C17: M1 | D17: M2 | E17: M3 | F17: M4 | G17: M5 | H17: M6 | I17: M7 | J17: M8 | K17: M9 | L17: M10 | M17: M11 | N17: M12 | O17: TOTAL
B18: Merchant | C18: 20 | D18: 25 | E18: 35 | F18: 45 | G18: 50 | H18: 65 | I18: 75 | J18: 80 | K18: 90 | L18: 100 | M18: 110 | N18: 125
B19: Starter | C19: =30%*C18 -> 6 | D19: =30%*D18+0.5 -> 8 | E19: =30%*E18-0.5 -> 10 | F19: =30%*F18+0.5 -> 14 | G19: =30%*G18 -> 15 | H19: =30%*H18+0.5 -> 20 | I19: =30%*I18+0.5 -> 23 | J19: =30%*J18 -> 24 | K19: =30%*K18 -> 27 | L19: =30%*L18 -> 30 | M19: =30%*M18 -> 33 | N19: =30%*N18+0.5 -> 38
B20: Professional | C20: =50%*C18 -> 10 | D20: =50%*D18-0.5 -> 12 | E20: =50%*E18+0.5 -> 18 | F20: =50%*F18-0.5 -> 22 | G20: =50%*G18 -> 25 | H20: =50%*H18-0.5 -> 32 | I20: =50%*I18-0.5 -> 37 | J20: =50%*J18 -> 40 | K20: =50%*K18 -> 45 | L20: =50%*L18 -> 50 | M20: =50%*M18 -> 55 | N20: =50%*N18-0.5 -> 62
B21: Enterprise | C21: =20%*C18 -> 4 | D21: =20%*D18 -> 5 | E21: =20%*E18 -> 7 | F21: =20%*F18 -> 9 | G21: =20%*G18 -> 10 | H21: =20%*H18 -> 13 | I21: =20%*I18 -> 15 | J21: =20%*J18 -> 16 | ... N21: =20%*N18 -> 25
B22: Subscription Revenue | C22: =(C19*PRICING!$C$5)+(C20*PRICING!$C$6)+(C21*PRICING!$C$7) -> 10980000 | D22: =(D19*PRICING!$C$5)+(D20*PRICING!$C$6)+(D21*PRICING!$C$7) -> 13575000 | E22: =(E19*PRICING!$C$5)+(E20*PRICING!$C$6)+(E21*PRICING!$C$7) -> 19365000 | F22: =(F19*PRICING!$C$5)+(F20*PRICING!$C$6)+(F21*PRICING!$C$7) -> 24555000 | G22: =(G19*PRICING!$C$5)+(G20*PRICING!$C$6)+(G21*PRICING!$C$7) -> 27450000 | H22: =(H19*PRICING!$C$5)+(H20*PRICING!$C$6)+(H21*PRICING!$C$7) -> 35535000 | I22: =(I19*PRICING!$C$5)+(I20*PRICING!$C$6)+(I21*PRICING!$C$7) -> 41025000 | J22: =(J19*PRICING!$C$5)+(J20*PRICING!$C$6)+(J21*PRICING!$C$7) -> 43920000 | ... N22: =(N19*PRICING!$C$5)+(N20*PRICING!$C$6)+(N21*PRICING!$C$7) -> 68475000 | O22: =SUM(C22:N22) -> 449580000
B23: Promotion Revenue | C23: =C18*PRICING!$C$21*(PRICING!$C$22/1000)*PRICING!$F$10 -> 975000 | D23: =D18*PRICING!$C$21*(PRICING!$C$22/1000)*PRICING!$F$10 -> 1218750 | E23: =E18*PRICING!$C$21*(PRICING!$C$22/1000)*PRICING!$F$10 -> 1706250 | F23: =F18*PRICING!$C$21*(PRICING!$C$22/1000)*PRICING!$F$10 -> 2193750 | G23: =G18*PRICING!$C$21*(PRICING!$C$22/1000)*PRICING!$F$10 -> 2437500 | H23: =H18*PRICING!$C$21*(PRICING!$C$22/1000)*PRICING!$F$10 -> 3168750 | I23: =I18*PRICING!$C$21*(PRICING!$C$22/1000)*PRICING!$F$10 -> 3656250 | J23: =J18*PRICING!$C$21*(PRICING!$C$22/1000)*PRICING!$F$10 -> 3900000 | ... N23: =N18*PRICING!$C$21*(PRICING!$C$22/1000)*PRICING!$F$10 -> 6093750 | O23: =SUM(C23:N23) -> 39975000
B24: Total Revenue | C24: =SUM(C22:C23) -> 11955000 | D24: =SUM(D22:D23) -> 14793750 | E24: =SUM(E22:E23) -> 21071250 | F24: =SUM(F22:F23) -> 26748750 | G24: =SUM(G22:G23) -> 29887500 | H24: =SUM(H22:H23) -> 38703750 | I24: =SUM(I22:I23) -> 44681250 | J24: =SUM(J22:J23) -> 47820000 | ... N24: =SUM(N22:N23) -> 74568750 | O24: =SUM(C24:N24) -> 489555000
B26: ARPM | C26: =C24/C18 -> 597750 | D26: =D24/D18 -> 591750 | E26: =E24/E18 -> 602035.71 | F26: =F24/F18 -> 594416.67 | G26: =G24/G18 -> 597750 | H26: =H24/H18 -> 595442.31 | I26: =I24/I18 -> 595750 | J26: =J24/J18 -> 597750 | ... N26: =N24/N18 -> 596550
B28: MODEL 3 (LOW)
C29: M1 | D29: M2 | E29: M3 | F29: M4 | G29: M5 | H29: M6 | I29: M7 | J29: M8 | K29: M9 | L29: M10 | M29: M11 | N29: M12 | O29: TOTAL
B30: Merchant | C30: 15 | D30: 20 | E30: 25 | F30: 35 | G30: 40 | H30: 45 | I30: 50 | J30: 65 | K30: 70 | L30: 75 | M30: 85 | N30: 100
B31: Starter | C31: =30%*C30+0.5 -> 5 | D31: =30%*D30 -> 6 | E31: =30%*E30-0.5 -> 7 | F31: =30%*F30+0.5 -> 11 | G31: =30%*G30 -> 12 | H31: =30%*H30+0.5 -> 14 | I31: =30%*I30 -> 15 | J31: =30%*J30+0.5 -> 20 | K31: =30%*K30 -> 21 | L31: =30%*L30+0.5 -> 23 | M31: =30%*M30+0.5 -> 26 | N31: =30%*N30 -> 30
B32: Professional | C32: =50%*C30-0.5 -> 7 | D32: =50%*D30 -> 10 | E32: =50%*E30+0.5 -> 13 | F32: =50%*F30-0.5 -> 17 | G32: =50%*G30 -> 20 | H32: =50%*H30-0.5 -> 22 | I32: =50%*I30 -> 25 | J32: =50%*J30-0.5 -> 32 | K32: =50%*K30 -> 35 | L32: =50%*L30-0.5 -> 37 | M32: =50%*M30-0.5 -> 42 | N32: =50%*N30 -> 50
B33: Enterprise | C33: =20%*C30 -> 3 | D33: =20%*D30 -> 4 | E33: =20%*E30 -> 5 | F33: =20%*F30 -> 7 | G33: =20%*G30 -> 8 | H33: =20%*H30 -> 9 | I33: =20%*I30 -> 10 | J33: =20%*J30 -> 13 | ... N33: =20%*N30 -> 20
B34: Subscription Revenue | C34: =(C31*PRICING!$C$5)+(C32*PRICING!$C$6)+(C33*PRICING!$C$7) -> 8085000 | D34: =(D31*PRICING!$C$5)+(D32*PRICING!$C$6)+(D33*PRICING!$C$7) -> 10980000 | E34: =(E31*PRICING!$C$5)+(E32*PRICING!$C$6)+(E33*PRICING!$C$7) -> 13875000 | F34: =(F31*PRICING!$C$5)+(F32*PRICING!$C$6)+(F33*PRICING!$C$7) -> 19065000 | G34: =(G31*PRICING!$C$5)+(G32*PRICING!$C$6)+(G33*PRICING!$C$7) -> 21960000 | H34: =(H31*PRICING!$C$5)+(H32*PRICING!$C$6)+(H33*PRICING!$C$7) -> 24555000 | I34: =(I31*PRICING!$C$5)+(I32*PRICING!$C$6)+(I33*PRICING!$C$7) -> 27450000 | J34: =(J31*PRICING!$C$5)+(J32*PRICING!$C$6)+(J33*PRICING!$C$7) -> 35535000 | ... N34: =(N31*PRICING!$C$5)+(N32*PRICING!$C$6)+(N33*PRICING!$C$7) -> 54900000 | O34: =SUM(C34:N34) -> 342375000
B35: Promotion Revenue | C35: =C30*PRICING!$C$21*(PRICING!$C$22/1000)*PRICING!$F$10 -> 731250 | D35: =D30*PRICING!$C$21*(PRICING!$C$22/1000)*PRICING!$F$10 -> 975000 | E35: =E30*PRICING!$C$21*(PRICING!$C$22/1000)*PRICING!$F$10 -> 1218750 | F35: =F30*PRICING!$C$21*(PRICING!$C$22/1000)*PRICING!$F$10 -> 1706250 | G35: =G30*PRICING!$C$21*(PRICING!$C$22/1000)*PRICING!$F$10 -> 1950000 | H35: =H30*PRICING!$C$21*(PRICING!$C$22/1000)*PRICING!$F$10 -> 2193750 | I35: =I30*PRICING!$C$21*(PRICING!$C$22/1000)*PRICING!$F$10 -> 2437500 | J35: =J30*PRICING!$C$21*(PRICING!$C$22/1000)*PRICING!$F$10 -> 3168750 | ... N35: =N30*PRICING!$C$21*(PRICING!$C$22/1000)*PRICING!$F$10 -> 4875000 | O35: =SUM(C35:N35) -> 30468750
B36: Total Revenue | C36: =SUM(C34:C35) -> 8816250 | D36: =SUM(D34:D35) -> 11955000 | E36: =SUM(E34:E35) -> 15093750 | F36: =SUM(F34:F35) -> 20771250 | G36: =SUM(G34:G35) -> 23910000 | H36: =SUM(H34:H35) -> 26748750 | I36: =SUM(I34:I35) -> 29887500 | J36: =SUM(J34:J35) -> 38703750 | ... N36: =SUM(N34:N35) -> 59775000 | O36: =SUM(C36:N36) -> 372843750
B38: ARPM | C38: =C36/C30 -> 587750 | D38: =D36/D30 -> 597750 | E38: =E36/E30 -> 603750 | F38: =F36/F30 -> 593464.29 | G38: =G36/G30 -> 597750 | H38: =H36/H30 -> 594416.67 | I38: =I36/I30 -> 597750 | J38: =J36/J30 -> 595442.31 | ... N38: =N36/N30 -> 597750
B40: MODEL 4 (IF REDUCED BY PERFORMANCE BASED ON MERCHANT ACQUISITION----NUMBERS FROM MODEL 3)
B41: % Fee per Merchant | C41: M1 | D41: M2 | E41: M3 | F41: M4 | G41: M5 | H41: M6 | I41: M7 | J41: M8 | K41: M9 | L41: M10 | M41: M11 | N41: M12 | O41: TOTAL
B42: (1st case) 15% Flat (S/P/E) | C42: =$C$34-((PRICING!$C$5*$C$31)*15%)-((PRICING!$C$6*$C$32)*15%)-((PRICING!$C$7*$C$33)*15%) -> 6872250
B43: (2nd case) 12% Flat (S/P/E) | C43: =$C$34-((PRICING!$C$5*$C$31)*12%)-((PRICING!$C$6*$C$32)*12%)-((PRICING!$C$7*$C$33)*12%) -> 7114800
B44: (3rd case) 10% Flat (S/P/E) | C44: =$C$34-((PRICING!$C$5*$C$31)*10%)-((PRICING!$C$6*$C$32)*10%)-((PRICING!$C$7*$C$33)*10%) -> 7276500
B45: (4th case) 15%S 12%P 10%E | C45: =C34-((PRICING!$C$5*C31)*15%)-((PRICING!$C$6*C32)*12%)-((PRICING!$C$7*C33)*10%) -> 7117890 | D45: =D34-((PRICING!$C$5*D31)*15%)-((PRICING!$C$6*D32)*12%)-((PRICING!$C$7*D33)*10%) -> 9672500 | E45: =E34-((PRICING!$C$5*E31)*15%)-((PRICING!$C$6*E32)*12%)-((PRICING!$C$7*E33)*10%) -> 12227110 | F45: =F34-((PRICING!$C$5*F31)*15%)-((PRICING!$C$6*F32)*12%)-((PRICING!$C$7*F33)*10%) -> 16790390 | G45: =G34-((PRICING!$C$5*G31)*15%)-((PRICING!$C$6*G32)*12%)-((PRICING!$C$7*G33)*10%) -> 19345000 | H45: =H34-((PRICING!$C$5*H31)*15%)-((PRICING!$C$6*H32)*12%)-((PRICING!$C$7*H33)*10%) -> 21626640 | I45: =I34-((PRICING!$C$5*I31)*15%)-((PRICING!$C$6*I32)*12%)-((PRICING!$C$7*I33)*10%) -> 24181250 | J45: =J34-((PRICING!$C$5*J31)*15%)-((PRICING!$C$6*J32)*12%)-((PRICING!$C$7*J33)*10%) -> 31299140 | ... N45: =N34-((PRICING!$C$5*N31)*15%)-((PRICING!$C$6*N32)*12%)-((PRICING!$C$7*N33)*10%) -> 48362500 | O45: =SUM(C45:N45) -> 301583200
B46: Promotion Revenue | C46: =C35 -> 731250 | D46: =D35 -> 975000 | E46: =E35 -> 1218750 | F46: =F35 -> 1706250 | G46: =G35 -> 1950000 | H46: =H35 -> 2193750 | I46: =I35 -> 2437500 | J46: =J35 -> 3168750 | ... N46: =N35 -> 4875000 | O46: =SUM(C46:N46) -> 30468750
B47: Total Revenue (Mix SR + PR) | C47: =C45+C46 -> 7849140 | D47: =D45+D46 -> 10647500 | E47: =E45+E46 -> 13445860 | F47: =F45+F46 -> 18496640 | G47: =G45+G46 -> 21295000 | H47: =H45+H46 -> 23820390 | I47: =I45+I46 -> 26618750 | J47: =J45+J46 -> 34467890 | ... N47: =N45+N46 -> 53237500 | O47: =SUM(O45:O46) -> 332051950
B49: Total Decrease @/month | C49: =C34-C45 -> 967110
...

Sheet COST STRUCTURE
B2: COST STRUCTURE (not final)
B4: Cost | C4: M-3 | D4: M-2 | E4: M-1 | F4: M1 | G4: M2 | H4: M3 | I4: M4 | J4: M5 | K4: M6 | L4: M7 | M4: M8 | N4: M9 | O4: M10 | P4: M11 | Q4: M12 | R4: TOTAL
B5: A. FIXED COST (biaya tetap per bulan)
B6: Developer (3 people) | C6: 15000000 | D6: 15000000 | E6: 15000000 | F6: 0 | G6: 0 | H6: 0 | I6: 0 | J6: 0 | K6: 0 | L6: 0 | M6: 0 | N6: 0 | O6: 0 | P6: 0 | Q6: 0 | R6: =SUM(C6:Q6) -> 45000000
B7: Server & IT Maintenance | C7: 0 | D7: 0 | E7: 0 | F7: 250000 | G7: 250000 | H7: 250000 | I7: 250000 | J7: 250000 | K7: 250000 | L7: 250000 | M7: 250000 | N7: 250000 | O7: 250000 | P7: 250000 | Q7: 250000 | R7: =SUM(C7:Q7) -> 3000000
B8: Domain | C8: 0 | D8: 0 | E8: 0 | F8: 200000 | G8: 200000 | H8: 200000 | I8: 200000 | J8: 200000 | K8: 200000 | L8: 200000 | M8: 200000 | N8: 200000 | O8: 200000 | P8: 200000 | Q8: 200000 | R8: =SUM(C8:Q8) -> 2400000
B9: Google Play | C9: 0 | D9: 0 | E9: 0 | F9: 500000 | G9: 0 | H9: 0 | I9: 0 | J9: 0 | K9: 0 | L9: 0 | M9: 0 | N9: 0 | O9: 0 | P9: 0 | Q9: 0 | R9: =SUM(C9:Q9) -> 500000
B10: App Store | C10: 0 | D10: 0 | E10: 0 | F10: 1800000 | G10: 0 | H10: 0 | I10: 0 | J10: 0 | K10: 0 | L10: 0 | M10: 0 | N10: 0 | O10: 0 | P10: 0 | Q10: 0 | R10: =SUM(C10:Q10) -> 1800000
B11: Salary Founder (4 people) | C11: =5000000*4 -> 20000000 | D11: =5000000*4 -> 20000000 | E11: =5000000*4 -> 20000000 | F11: =5000000*4 -> 20000000 | G11: =5000000*4 -> 20000000 | H11: =5000000*4 -> 20000000 | I11: =5000000*4 -> 20000000 | J11: =5000000*4 -> 20000000 | ... Q11: =5000000*4 -> 20000000 | R11: =SUM(C11:Q11) -> 300000000
B12: Salary Marketer/Sales | C12: 10000000 | D12: 10000000 | E12: 10000000 | F12: =5000000*2 -> 10000000 | G12: =5000000*2 -> 10000000 | H12: =5000000*2 -> 10000000 | I12: =5000000*2 -> 10000000 | J12: =5000000*2 -> 10000000 | K12: =5000000*2 -> 10000000 | L12: =5000000*2 -> 10000000 | M12: =5000000*2 -> 10000000 | ... Q12: =5000000*2 -> 10000000 | R12: =SUM(C12:Q12) -> 150000000
B13: Artist | C13: 3000000 | D13: 0 | E13: 0 | F13: 0 | G13: 0 | H13: 0 | I13: 0 | J13: 0 | K13: 0 | L13: 0 | M13: 0 | N13: 0 | O13: 0 | P13: 0 | Q13: 0 | R13: =SUM(C13:Q13) -> 3000000
B14: License (HAKI, Logo, &L^2) | C14: 0 | D14: 0 | E14: 3000000 | F14: 0 | G14: 0 | H14: 0 | I14: 0 | J14: 0 | K14: 0 | L14: 0 | M14: 0 | N14: 0 | O14: 0 | P14: 0 | Q14: 0 | R14: =SUM(C14:Q14) -> 3000000
B15: PT & Badan Hukum &L^2 | C15: 10000000 | D15: 0 | E15: 0 | F15: 0 | G15: 0 | H15: 0 | I15: 0 | J15: 0 | K15: 0 | L15: 0 | M15: 0 | N15: 0 | O15: 0 | P15: 0 | Q15: 0 | R15: =SUM(C15:Q15) -> 10000000
B16: AI Development * | C16: 0 | D16: 0 | E16: 1700000 | F16: 2000000 | G16: 2000000 | H16: 2000000 | I16: 2000000 | J16: 2000000 | K16: 2000000 | L16: 2000000 | M16: 2000000 | N16: 2000000 | O16: 2000000 | P16: 2000000 | Q16: 2000000 | R16: =SUM(C16:Q16) -> 25700000
B17: Total Fixed Cost | C17: =SUM(C5:C16) -> 58000000 | D17: =SUM(D5:D16) -> 45000000 | E17: =SUM(E5:E16) -> 49700000 | F17: =SUM(F6:F16) -> 34750000 | G17: =SUM(G6:G16) -> 32450000 | H17: =SUM(H6:H16) -> 32450000 | I17: =SUM(I6:I16) -> 32450000 | J17: =SUM(J6:J16) -> 32450000 | K17: =SUM(K6:K16) -> 32450000 | L17: =SUM(L6:L16) -> 32450000 | M17: =SUM(M6:M16) -> 32450000 | ... R17: =SUM(R6:R16) -> 544400000
B18: B. VARIABLE COST (berubah sesuai aktivitas)
B19: Merchant CAC (200rb x Target) | C19: 0 | D19: 0 | E19: 0 | F19: =PRICING!C19*'GROWTH PROJECTION'!C6 -> 10000000 | G19: =PRICING!C19*('GROWTH PROJECTION'!C7-'GROWTH PROJECTION'!C6) -> 3000000 | H19: =PRICING!C19*('GROWTH PROJECTION'!C8-'GROWTH PROJECTION'!C7) -> 3400000 | I19: =PRICING!C19*('GROWTH PROJECTION'!C9-'GROWTH PROJECTION'!C8) -> 3600000 | J19: =PRICING!C19*('GROWTH PROJECTION'!C10-'GROWTH PROJECTION'!C9) -> 4000000 | K19: =PRICING!C19*('GROWTH PROJECTION'!C11-'GROWTH PROJECTION'!C10) -> 5000000 | L19: =PRICING!C19*('GROWTH PROJECTION'!C12-'GROWTH PROJECTION'!C11) -> 5000000 | M19: =PRICING!C19*('GROWTH PROJECTION'!C13-'GROWTH PROJECTION'!C12) -> 6000000 | N19: =PRICING!C$19*('GROWTH PROJECTION'!C14-'GROWTH PROJECTION'!C13) -> 6000000 | O19: =PRICING!C$19*('GROWTH PROJECTION'!C15-'GROWTH PROJECTION'!C14) -> 7000000 | P19: =PRICING!$C19*('GROWTH PROJECTION'!C16-'GROWTH PROJECTION'!C15) -> 7000000 | Q19: =PRICING!$C19*('GROWTH PROJECTION'!C17-'GROWTH PROJECTION'!C16) -> 8000000 | R19: =SUM(F19:Q19) -> 68000000
B20: Growth Cost (Trial Subsidy) | C20: 0 | D20: 0 | E20: 0 | F20: 2250000 | G20: 2250000 | H20: 2250000 | I20: 2250000 | J20: 2250000 | K20: 2250000 | L20: 2250000 | M20: 2250000 | N20: 2250000 | O20: 2250000 | P20: 2250000 | Q20: 2250000 | R20: =SUM(F20:Q20) -> 27000000
B21: Marketing (Ads, KOL, SEO) | C21: 0 | D21: 0 | E21: 0 | F21: 4166667 | G21: 4166667 | H21: 4166667 | I21: 4166667 | J21: 4166667 | K21: 4166667 | L21: 4166667 | M21: 4166667 | N21: 4166667 | O21: 4166667 | P21: 4166667 | Q21: 4166667 | R21: =SUM(F21:Q21)-4 -> 50000000
B22: Promotion & Referral | C22: 0 | D22: 0 | E22: 0 | F22: 500000 | G22: 500000 | H22: 500000 | I22: 500000 | J22: 500000 | K22: 500000 | L22: 500000 | M22: 500000 | N22: 500000 | O22: 500000 | P22: 500000 | Q22: 500000 | R22: =SUM(F22:Q22) -> 6000000
B23: Notification (EMAIL) | C23: 0 | D23: 0 | E23: 0 | F23: 333333 | G23: 333333 | H23: 333333 | I23: 333333 | J23: 333333 | K23: 333333 | L23: 333333 | M23: 333333 | N23: 333333 | O23: 333333 | P23: 333333 | Q23: 333333 | R23: =SUM(F23:Q23)+4 -> 4000000
B24: ASO | C24: 0 | D24: 0 | E24: 0 | F24: 50000 | G24: 50000 | H24: 50000 | I24: 50000 | J24: 50000 | K24: 50000 | L24: 50000 | M24: 50000 | N24: 50000 | O24: 50000 | P24: 50000 | Q24: 50000 | R24: =SUM(F24:Q24) -> 600000
B25: Total Variable Cost | C25: =SUM(C19:C24) -> 0 | D25: =SUM(D19:D24) -> 0 | E25: =SUM(E19:E24) -> 0 | F25: =SUM(F19:F24) -> 17300000 | G25: =SUM(G19:G24) -> 10300000 | H25: =SUM(H19:H24) -> 10700000 | I25: =SUM(I19:I24) -> 10900000 | J25: =SUM(J19:J24) -> 11300000 | ... R25: =SUM(R19:R24) -> 155600000
B26: TOTAL COST | C26: =C17+C25 -> 58000000 | D26: =D17+D25 -> 45000000 | E26: =E17+E25 -> 49700000 | F26: =F17+F25 -> 52050000 | G26: =G17+G25 -> 42750000 | H26: =H17+H25 -> 43150000 | I26: =I17+I25 -> 43350000 | J26: =J17+J25 -> 43750000 | ... R26: =R17+R25 -> 700000000
B28: Anything else?
B29: * = Ranged from 100k - 2m depends on the prompts
E31: =SUM(C17:H17)+SUM(F25:H25) -> 290650000

Sheet P&L STATEMENT
B2: P&L STATEMENT (not final)
B4: Keterangan | C4: M1 | D4: M2 | E4: M3 | F4: M4 | G4: M5 | H4: M6 | I4: M7 | J4: M8 | K4: M9 | L4: M10 | M4: M11 | N4: M12 | O4: TOTAL
B5: A. REVENUE
B6: Subscription Revenue | C6: ='REVENUE MODEL'!C45 -> 7117890 | D6: ='REVENUE MODEL'!D10 -> 35535000 | E6: ='REVENUE MODEL'!E10 -> 44818000 | F6: ='REVENUE MODEL'!F10 -> 54900000 | G6: ='REVENUE MODEL'!G10 -> 65880000 | H6: ='REVENUE MODEL'!H10 -> 79455000 | I6: ='REVENUE MODEL'!I10 -> 93330000 | J6: ='REVENUE MODEL'!J10 -> 109800000 | K6: ='REVENUE MODEL'!K10 -> 126270000 | ... N6: ='REVENUE MODEL'!N10 -> 186660000 | O6: =SUM(C6:N6) -> 1113800890
B7: Promotion Revenue | C7: ='REVENUE MODEL'!C11 -> 2437500 | D7: ='REVENUE MODEL'!D11 -> 3168750 | E7: ='REVENUE MODEL'!E11 -> 3997500 | F7: ='REVENUE MODEL'!F11 -> 4875000 | G7: ='REVENUE MODEL'!G11 -> 5850000 | H7: ='REVENUE MODEL'!H11 -> 7068750 | I7: ='REVENUE MODEL'!I11 -> 8287500 | J7: ='REVENUE MODEL'!J11 -> 9750000 | ... O7: ='REVENUE MODEL'!O11 -> 100766250
B8: Total Revenue | C8: =SUM(C6:C7) -> 9555390 | D8: =SUM(D6:D7) -> 38703750 | E8: =SUM(E6:E7) -> 48815500 | F8: =SUM(F6:F7) -> 59775000 | G8: =SUM(G6:G7) -> 71730000 | H8: =SUM(H6:H7) -> 86523750 | I8: =SUM(I6:I7) -> 101617500 | J8: =SUM(J6:J7) -> 119550000 | ... O8: =SUM(O6:O7) -> 1214567140
B9: B. COST OF GOODS SOLD | C9: 0 | D9: 0 | E9: 0 | F9: 0 | G9: 0 | H9: 0 | I9: 0 | J9: 0 | K9: 0 | L9: 0 | M9: 0 | N9: 0 | O9: 0
B10: C. GROSS PROFIT | C10: =C8-C9 -> 9555390 | D10: =D8-D9 -> 38703750 | E10: =E8-E9 -> 48815500 | F10: =F8-F9 -> 59775000 | G10: =G8-G9 -> 71730000 | H10: =H8-H9 -> 86523750 | I10: =I8-I9 -> 101617500 | J10: =J8-J9 -> 119550000 | ... O10: =O8-O9 -> 1214567140
B11: D. OPERATING EXPENSES
B12: Total Operating Cost | C12: ='COST STRUCTURE'!F26 -> 52050000 | D12: ='COST STRUCTURE'!G26 -> 42750000 | E12: ='COST STRUCTURE'!H26 -> 43150000 | F12: ='COST STRUCTURE'!I26 -> 43350000 | G12: ='COST STRUCTURE'!J26 -> 43750000 | H12: ='COST STRUCTURE'!K26 -> 44750000 | I12: ='COST STRUCTURE'!L26 -> 44750000 | J12: ='COST STRUCTURE'!M26 -> 45750000 | ... N12: ='COST STRUCTURE'!Q26 -> 47750000 | O12: =SUM(C12:N12) -> 547300000
B13: E. EBITDA | C13: =C10-C12 -> -42494610 | D13: =D10-D12 -> -4046250 | E13: =E10-E12 -> 5665500 | F13: =F10-F12 -> 16425000 | G13: =G10-G12 -> 27980000 | H13: =H10-H12 -> 41773750 | I13: =I10-I12 -> 56867500 | J13: =J10-J12 -> 73800000 | ... O13: =O10-O12 -> 667267140
B14: F. DEPRECIATION & AMORTIZATION | C14: 0 | D14: 0 | E14: 0 | F14: 0 | G14: 0 | H14: 0 | I14: 0 | J14: 0 | K14: 0 | L14: 0 | M14: 0 | N14: 0 | O14: 0
B15: G. NET PROFIT (EBT) | C15: =C13-C14 -> -42494610 | D15: =D13-D14 -> -4046250 | E15: =E13-E14 -> 5665500 | F15: =F13-F14 -> 16425000 | G15: =G13-G14 -> 27980000 | H15: =H13-H14 -> 41773750 | I15: =I13-I14 -> 56867500 | J15: =J13-J14 -> 73800000 | ... O15: =O13-O14 -> 667267140
B16: H. EAT | C16: =C15+(0.5%*C15) -> -42707083 | D16: =D15+(0.5%*D15) -> -4066481.2 | E16: =E15+(0.5%*E15) -> 5693827.5 | F16: =F15-(0.5%*F15) -> 16342875 | G16: =G15-(0.5%*G15) -> 27840100 | H16: =H15-(0.5%*H15) -> 41564881 | I16: =I15-(0.5%*I15) -> 56583162 | J16: =J15-(0.5%*J15) -> 73431000 | K16: =K15-(0.5%*K15) -> 91273838 | L16: =L15-(0.5%*L15) -> 1.1094623e+08 | M16: =M15-(0.5%*M15) -> 131912125 | N16: =N15-(0.5%*N15) -> 154707575 | O16: =SUM(C16:N16) -> 6.6352205e+08 | P16: - 0,5% pajak
O18: =20%*O15 -> 133453428
O19: =O18/12 -> 11121119
O20: 5000000
O21: =O19+O20 -> 16121119 | P21: @/month

Sheet FUNDING ANALYSIS
B2: CAPITAL DEPLOYMENT PLAN (not final)
B4: 1. PRE-LAUNCH INVESTMENT Biaya sebelum launching (sekali bayar) | D4: (M-3 - M0) | F4: 2. GO-TO MARKET PLAN Akselerasi awal untuk traction | J4: (M1 - M3) | L4: 3. MONTHLY RUNWAY PLAN Proyeksi Revenue, Expense, Cash Flow | P4: (M1 - M12)
B5: Component | C5: Description | D5: Amount (IDR) | F5: Component | G5: M1 | H5: M2 | I5: M3 | J5: Total (3 Months) | L5: Month | M5: Total Revenue | N5: Total Expense | O5: Net Cash Flow | P5: Ending Cash Balance
B6: 1. Product Development | C6: 3 Months Development | D6: 45000000 | F6: Ads (User Acquisition) | G6: 5000000 | H6: 5000000 | I6: 5000000 | J6: =SUM(G6:I6) -> 15000000 | L6: M1 | M6: ='REVENUE MODEL'!C12 -> 29887500
B7: 2. Server & Infrastructure Setup | C7: Initial Server, DB, Tools | D7: 3000000 | F7: Merchant Trial Subsidy | J7: =SUM(G7:I7) -> 0 | L7: M2 | M7: ='REVENUE MODEL'!D$12 -> 38703750
B8: 3. Testing & QA | C8: Testing, Bug Fixing | D8: 2000000 | F8: Merchant Acquisition (MAC) | G8: =PRICING!C19*'GROWTH PROJECTION'!C6 -> 10000000 | H8: =PRICING!C19*('GROWTH PROJECTION'!C7-'GROWTH PROJECTION'!C6) -> 3000000 | I8: =PRICING!C19*('GROWTH PROJECTION'!C8-'GROWTH PROJECTION'!C7) -> 3400000 | J8: =SUM(G8:I8) -> 16400000 | L8: M3 | M8: ='REVENUE MODEL'!E$12 -> 48815500
B9: 4. Deployment (Mobile Phone) | C9: Play Store & AppStore | D9: 2300000 | F9: Influencer / KOL | G9: 2000000 | H9: 2000000 | I9: 2000000 | J9: =SUM(G9:I9) -> 6000000 | L9: M4 | M9: ='REVENUE MODEL'!F$12 -> 59775000
B10: 5. Domain | C10: Domain Purchasement | D10: 2400000 | F10: Content & SEO | G10: 500000 | H10: 500000 | I10: 500000 | J10: =SUM(G10:I10) -> 1500000 | L10: M5 | M10: ='REVENUE MODEL'!G$12 -> 71730000
B11: 6. Law & Legal | C11: Build PT, Legal Basic | D11: 10000000 | F11: Partnership / Activation | G11: 500000 | H11: 500000 | I11: 500000 | J11: =SUM(G11:I11) -> 1500000 | L11: M6 | M11: ='REVENUE MODEL'!H$12 -> 86523750
B12: 6. Salary | C12: Founder & Marketer | D12: 90000000 | F12: TOTAL GTM INVESTMENT | G12: =SUM(G6:G11) -> 18000000 | H12: =SUM(H6:H11) -> 11000000 | I12: =SUM(I6:I11) -> 11400000 | J12: =SUM(G12:I12) -> 40400000 | L12: M7 | M12: ='REVENUE MODEL'!I$12 -> 101617500
B13: 7. Miscellaneous | C13: Tools, Software, Others | D13: 5000000 | F13: 💡Fokus 3 bulan pertama: validasi product-market fit & grow user + merchant | L13: M8 | M13: ='REVENUE MODEL'!J$12 -> 119550000
B14: TOTAL PRE-LAUNCH INVESTMENT | D14: =SUM(D6:D13) -> 159700000 | L14: M9 | M14: ='REVENUE MODEL'!K$12 -> 137482500
B15: 💡Pre-launch investment dikeluarkan sebelum aplikasi running. Periode: M3, M-2, M-1, M0 | L15: M10 | M15: ='REVENUE MODEL'!L$12 -> 158253750
L16: M11 | M16: ='REVENUE MODEL'!M$12 -> 179325000
L17: M12 | M17: ='REVENUE MODEL'!N$12 -> 203235000
F19: 5. FUNDRAISING SUMMARY (ROUND PRE-SEED) Ringkasan pendanaan yang akan diterima
B20: 4. FUNDING WATERFALL Berapa dana yang benar-benar perlu di-raise | F20: Keterangan | G20: Nilai | H20: W H A T F O R ? | I20: Penggunaan Dana
B21: Keterangan | C21: Amount (IDR) | F21: Dana yang dicari (Target raise) | G21: =C26 -> 437948050
B22: Total expense 12 bulan (incl. Pre launch) | C22: ='COST STRUCTURE'!R26 -> 700000000 | F22: Pre-money Valuation (estimasi) | G22: 1500000000 | I22: ✅ Mencapai 340 Merchant aktif
B23: (-) Revenue yang dihasilkan (12 bulan) | C23: ='REVENUE MODEL'!O47 -> 332051950 | F23: Post-money Valuation | G23: =G22+G21 -> 1937948050 | I23: ✅ 50.000 user terdaftar dan aktif
B24: Net cash need (sebelum buffer) | C24: =C22-C23 -> 367948050 | F24: Tipe instrumen | G24: Equity | I24: ✅ Positive contribution margin di M10
B25: (+) Safety buffer (20%) | C25: =10%*C22 -> 70000000 | F25: Equity yang dilepas | G25: 0.2 | I25: ✅ Runway 12+ bulan
B26: TARGET FUNDRAISE (ROUND PRE-SEED) | C26: =C24+C25 -> 437948050 | F26: Expected closing | G26: M-3 | I26: ✅ Siap untuk Seed Round
B27: 💡Angka buffer untuk proteksi risiko delay revenue / over budget
S28: 2
B30: 6. USE OF FUNDS (ALLOCATION) Rencana alokasi dana yang akan diterima
B31: Category | C31: Amount (IDR) | D31: % Allocation
B32: Product Development | C32: =SUM('COST STRUCTURE'!R6:R10)+SUM('COST STRUCTURE'!R13:R16) -> 94400000 | D32: =C32/$C$37 -> 0.118
B33: Marketing (User + Merchant acquisition) | C33: ='COST STRUCTURE'!R19+'COST STRUCTURE'!R21+'COST STRUCTURE'!R22 -> 124000000 | D33: =C33/$C$37 -> 0.155
B34: Operations & Team | C34: ='COST STRUCTURE'!R11+'COST STRUCTURE'!R12 -> 450000000 | D34: =C34/$C$37 -> 0.5625
B35: Merchant trial & subsidy | C35: ='COST STRUCTURE'!R20 -> 27000000 | D35: =C35/$C$37 -> 0.03375
B36: Buffer & Contingency | C36: ='COST STRUCTURE'!R23+'COST STRUCTURE'!R24+100000000 -> 104600000 | D36: =C36/$C$37 -> 0.13075
B37: TOTAL | C37: =SUM(C32:C36) -> 800000000 | D37: =C37/$C$37 -> 1
C38: 🟦 Product Development 🟥 Marketing 🟨 Operations & Team 🟩 Merchant Trial & Subsidy 🟧 Buffer & Contingency
E53: High
B54: Component | C54: Low | D54: Mid | E54: 60000000
B55: Developer (3 Month) | C55: 45000000 | D55: 55000000 | E55: 27500000
B56: IT Needs (1 Year) | C56: 12500000 | D56: 20000000 | E56: 180000000
B57: Marketing | C57: 50000000 | D57: 115000000 | E57: 336000000
B58: Founder Salary | C58: 96000000 | D58: 240000000 | E58: 200000000
...

Sheet CASHFLOW STATEMENT
B2: CASHFLOW STATEMENT (not final)
B4: Keterangan | C4: M1 | D4: M2 | E4: M3 | F4: M4 | G4: M5 | H4: M6 | I4: M7 | J4: M8 | K4: M9 | L4: M10 | M4: M11 | N4: M12 | O4: TOTAL
B5: A. OPENING CASH | C5: 500000000 | D5: =C14 -> 477837500 | E5: =D14 -> 473791250 | F5: =E14 -> 479456750 | G5: =F14 -> 495881750 | H5: =G14 -> 523861750 | I5: =H14 -> 565635500 | J5: =I14 -> 622503000 | K5: =J14 -> 696303000 | ... N5: =M14 -> 1032114250
B6: B. CASH INFLOW
B7: Revenue (Cash Basis) | C7: ='REVENUE MODEL'!C12 -> 29887500 | D7: ='REVENUE MODEL'!D12 -> 38703750 | E7: ='REVENUE MODEL'!E12 -> 48815500 | F7: ='REVENUE MODEL'!F12 -> 59775000 | G7: ='REVENUE MODEL'!G12 -> 71730000 | H7: ='REVENUE MODEL'!H12 -> 86523750 | I7: ='REVENUE MODEL'!I12 -> 101617500 | J7: ='REVENUE MODEL'!J12 -> 119550000 | ... N7: ='REVENUE MODEL'!N12 -> 203235000 | O7: =SUM(C7:N7) -> 1234899250
B8: Funding Received | C8: =C5 -> 500000000 | O8: =SUM(C8:N8) -> 500000000
B9: Total Cash Inflow | C9: =C7+C8 -> 529887500 | D9: =D7+D8 -> 38703750 | E9: =E7+E8 -> 48815500 | F9: =F7+F8 -> 59775000 | G9: =G7+G8 -> 71730000 | H9: =H7+H8 -> 86523750 | I9: =I7+I8 -> 101617500 | J9: =J7+J8 -> 119550000 | ... N9: =N7+N8 -> 203235000 | O9: =SUM(C9:N9) -> 1734899250
B10: C. CASH OUTFLOW
B11: Total Operational Cash | C11: ='P&L STATEMENT'!C12 -> 52050000 | D11: ='P&L STATEMENT'!D12 -> 42750000 | E11: ='P&L STATEMENT'!E12 -> 43150000 | F11: ='P&L STATEMENT'!F12 -> 43350000 | G11: ='P&L STATEMENT'!G12 -> 43750000 | H11: ='P&L STATEMENT'!H12 -> 44750000 | I11: ='P&L STATEMENT'!I12 -> 44750000 | J11: ='P&L STATEMENT'!J12 -> 45750000 | ... N11: ='P&L STATEMENT'!N12 -> 47750000 | O11: =SUM(C11:N11) -> 547300000
B12: Total Cash Outflow | C12: =C11 -> 52050000 | D12: =D11 -> 42750000 | E12: =E11 -> 43150000 | F12: =F11 -> 43350000 | G12: =G11 -> 43750000 | H12: =H11 -> 44750000 | I12: =I11 -> 44750000 | J12: =J11 -> 45750000 | ... N12: =N11 -> 47750000 | O12: =SUM(C12:N12) -> 547300000
B13: D. NET CASH FLOW (B-C) | C13: =C9-C12 -> 477837500 | D13: =D9-D12 -> -4046250 | E13: =E9-E12 -> 5665500 | F13: =F9-F12 -> 16425000 | G13: =G9-G12 -> 27980000 | H13: =H9-H12 -> 41773750 | I13: =I9-I12 -> 56867500 | J13: =J9-J12 -> 73800000 | ... O13: =O9-O12 -> 1187599250
B14: E. CLOSING CASH (A-D) | C14: =C13 -> 477837500 | D14: =D5+D13 -> 473791250 | E14: =E5+E13 -> 479456750 | F14: =F5+F13 -> 495881750 | G14: =G5+G13 -> 523861750 | H14: =H5+H13 -> 565635500 | I14: =I5+I13 -> 622503000 | J14: =J5+J13 -> 696303000 | K14: =K5+K13 -> 788035500 | ... N14: =N5+N13 -> 1187599250
B16: *make sure revenue and cost in a cash basis (not accrual)
B17: *update funding earlier if any capital added
B19: Principles:
B20: Net Cash Flow = TCI - TCO
B21: Closing Cash = Opening Cash + NCF

Sheet UNIT ECONOMICS
B2: UNIT ECONOMICS (not final)

Sheet BREAK EVEN
B2: BREAK EVEN ANALYSIS (not final)

Sheet BURN RATE
B2: BURN RATE (not final)
B4: Keterangan | C4: M1 | D4: M2 | E4: M3 | F4: M4 | G4: M5 | H4: M6 | I4: M7 | J4: M8 | K4: M9 | L4: M10 | M4: M11 | N4: M12 | O4: AVERAGE

Sheet VALUATION
B2: VALUATION (not final)

Sheet DASHBOARD

Sheet KPI
B2: Merchant KPI | C2: Value
B3: CAC Merchant | C3: 200000
B4: ARPM (Yr1) | C4: 699000
B5: Retention | C5: 0.85
B6: Est. LTV | C6: 12582000
B8: User KPI | C8: Value
B9: Initial User | C9: 1000
B10: Activation Rate | C10: 0.7
B11: Repeat Visit | C11: 5
